Workbook
Name Appendix_1_Range: 'APPENDIX 1'!$B$3:$R$51
Name Appendix_10: 'APPENDIX 10'!$B$3:$K$37
Name Appendix_11: 'APPENDIX 11'!$B$3:$Q$37
Name Appendix_12: 'APPENDIX 12'!$B$3:$Q$37
Name Appendix_13: 'APPENDIX 13'!$B$3:$Q$37
Name Appendix_14: 'APPENDIX 14'!$B$3:$Q$37
Name Appendix_15: 'APPENDIX 15'!$B$3:$Q$37
Name Appendix_16: 'APPENDIX 16'!$B$3:$Q$37
Name Appendix_17: 'APPENDIX 17'!$B$3:$Q$37
Name Appendix_18: 'APPENDIX 18'!$B$3:$Q$37
Name Appendix_19: 'APPENDIX 19'!$B$3:$Q$37
Name Appendix_2: 'APPENDIX 2'!$B$3:$R$38
Name Appendix_20: 'APPENDIX 20'!$B$3:$I$38
Name Appendix_21: 'APPENDIX 21'!$B$3:$R$50
Name Appendix_22: 'APPENDIX 22'!$B$3:$Q$50
Name Appendix_23: 'APPENDIX 23'!$B$3:$Q$50
Name Appendix_24: 'APPENDIX 24'!$B$3:$Q$50
Name Appendix_25: 'APPENDIX 25'!$B$3:$Q$50
Name Appendix_26: 'APPENDIX 26'!$B$3:$Q$50
Name Appendix_27: 'APPENDIX 27'!$B$3:$Q$50
Name Appendix_28: 'APPENDIX 28'!$B$3:$Q$50
Name Appendix_29: 'APPENDIX 29'!$B$3:$Q$50
Name Appendix_3: 'APPENDIX 3'!$B$3:$R$9
Name Appendix_30: 'APPENDIX 30'!$B$3:$Q$50
Name Appendix_31: 'APPENDIX 31'!$B$3:$Q$50
Name Appendix_32: 'APPENDIX 32'!$B$3:$Q$50
Name Appendix_33: 'APPENDIX 33'!$B$3:$Q$50
Name Appendix_34: 'APPENDIX 34'!$B$3:$Q$50
Name Appendix_35: 'APPENDIX 35'!$B$3:$Q$50
Name Appendix_36: 'APPENDIX 36'!$B$3:$Q$50
Name Appendix_37: 'APPENDIX 37'!$B$3:$Q$50
Name Appendix_38: 'APPENDIX 38'!$B$3:$Q$50
Name Appendix_39: 'APPENDIX 39'!$B$3:$Q$50
Name Appendix_4: 'APPENDIX 4'!$B$3:$H$52
Name Appendix_40: 'APPENDIX 40'!$B$3:$Q$50
Name Appendix_41: 'APPENDIX 41'!$B$3:$Q$50
Name Appendix_42: 'APPENDIX 42'!$B$3:$Q$50
Name Appendix_43: 'APPENDIX 43'!$B$3:$Q$50
Name Appendix_44: 'APPENDIX 44'!$B$3:$Q$50
Name Appendix_45: 'APPENDIX 45'!$B$3:$Q$9
Name Appendix_46: 'APPENDIX 46'!$B$3:$L$33
Name Appendix_47: 'APPENDIX 47'!$B$3:$H$43
Name Appendix_48: 'APPENDIX 48'!$B$3:$H$32
Name Appendix_49: 'APPENDIX 49'!$B$3:$H$9
Name Appendix_50: 'APPENDIX 50'!$B$2:$P$28
Name Appendix_51: 'APPENDIX 51'!$B$3:$L$44
Name Appendix_52: 'APPENDIX 52'!$B$3:$L$44
Name Appendix_53: 'APPENDIX 53'!$B$3:$H$36
Name Appendix_54: 'APPENDIX 54'!$B$3:$H$63
Name Appendix_55I: #REF!
Name Appendix_55II: #REF!
Name Appendix_55III: #REF!
Name Appendix_55IV: #REF!
Name Appendix_55V: #REF!
Name Appendix_55VI: #REF!
Name Appendix_56: #REF!
Name Appendix_57: #REF!
Name Appendix_5I: 'APPENDIX 5 I'!$B$3:$L$43
Name Appendix_5II: 'APPENDIX 5 II'!$B$2:$L$43
Name Appendix_5III: 'APPENDIX 5 III'!$B$2:$K$43

Sheet Details
F7: INSURANCE REGULATORY AUTHORITY | M7: Quarterly | N7: 2010
M8: Annual | N8: 2011
N9: 2012
N10: 2013
N11: 2015
F12: TYPE OF INDUSTRY STATISTICS | G12: ANNUAL AUDITED | N12: 2016
N13: 2017
N14: 2019
F15: FOR THE YEAR | G15: 2024 | N15: 2020
N16: 2021
F18: PERIOD ENDED | G18: 31ST DECEMBER 2024 | N18: 2022
N19: 2024
F21: PREPARED BY | G21: INSURANCE REGULATORY AUTHORITY
G22: AUGUST, 2025
N23: 2024
N24: 2025
N25: 2026
N26: 2027
N27: 2028
N28: 2029
N29: 2030
N30: 2031
N31: 2032
N32: 2033
N33: 2034
N34: 2035
... N51: 2052

Sheet Reliance & Limitations
B3: RELIANCE AND LIMITATIONS
B4: The insurance information contained in this workbook has been extracted from the annual audited returns submitted to the Authority in line with Section 54 of the Insurance Act. No adjustments have been made to the returns’ data except where necessary in consultation with the affected insurer(s) or reinsurer(s). The publication of any summary of the returns in this report does not necessarily mean that the returns so summarized have satisfied all the requirements of the Insurance Act, or that the Commissioner of Insurance approves the accuracy or the contents of the returns Where necessary, figures have been adjusted to eliminate errors in totals due to rounding off, and are given in thousands Kenya shillings (‘000’ KES) except where otherwise stated. Also to note, the 2024 data is provisional. The report did not incorporate annual audited data for Trident Insurance Company Limited and KUSCCO Mutual Assurance Limited due to non-submission of the annual returns. However, unaudited Q4 2024 data for KUSCCO Mutual Assurance Limited was used in place of the audited figures. In addition, data for Invesco Assurance Company Limited was excluded as the company was placed under statutory management during the year under review.

Sheet Contents
E2: INSURANCE REGULATORY AUTHORITY
E4: 2024 DATA
E5: TABLE of CONTENTS
B6: Sheet Name | C6: Label | E6: Link | F6: Description
B8: T1 | C8: Trends 1 | E8: =HYPERLINK("#'" & B8 & "'!A1", C8) -> Trends 1 | F8: Economy and Insurance Industry Trends
B9: T2 | C9: Trends 2 | E9: =HYPERLINK("#'" & B9 & "'!A1", C9) -> Trends 2 | F9: Trends in Long-Term Insurance Business
B10: T3 | C10: Trends 3 | E10: =HYPERLINK("#'" & B10 & "'!A1", C10) -> Trends 3 | F10: Trends in General Insurance Business
B11: T4 | C11: Trends 4 | E11: =HYPERLINK("#'" & B11 & "'!A1", C11) -> Trends 4 | F11: Trends in Microinsurance Business
B12: T5 | C12: Trends 5 | E12: =HYPERLINK("#'" & B12 & "'!A1", C12) -> Trends 5 | F12: Trends in Re-insurance Business
B13: APPENDIX 1 | C13: APPENDIX 1 | E13: =HYPERLINK("#'" & B13 & "'!A1", C13) -> APPENDIX 1 | F13: Summary of Profit & Loss Accounts under General Insurance Business for the Year Ended 31.12.2024
B14: APPENDIX 2 | C14: APPENDIX 2 | E14: =HYPERLINK("#'" & B14 & "'!A1", C14) -> APPENDIX 2 | F14: Summary of Profit & Loss Accounts Long-Term Insurance Business for the Year Ended 31.12.2024
B15: APPENDIX 3 | C15: APPENDIX 3 | E15: =HYPERLINK("#'" & B15 & "'!A1", C15) -> APPENDIX 3 | F15: Summary of Profit & Loss Accounts Microinsurance Business for the Year Ended 31.12.2024
B16: APPENDIX 4 | C16: APPENDIX 4 | E16: =HYPERLINK("#'" & B16 & "'!A1", C16) -> APPENDIX 4 | F16: Summary of Net Commissions and Management Expenses for the Year Ended 31.12.2024
B17: APPENDIX 5 I | C17: APPENDIX 5 I | E17: =HYPERLINK("#'" & B17 & "'!A1", C17) -> APPENDIX 5 I | F17: Summary of Long Term Insurance Business Balance Sheets as at 31.12.2024
B18: APPENDIX 5 II | C18: APPENDIX 5 II | E18: =HYPERLINK("#'" & B18 & "'!A1", C18) -> APPENDIX 5 II | F18: Summary of Long Term Insurance Business Balance Sheets as at 31.12.2024
B19: APPENDIX 5 III | C19: APPENDIX 5 III | E19: =HYPERLINK("#'" & B19 & "'!A1", C19) -> APPENDIX 5 III | F19: Summary of Long Term Insurance Business Balance Sheets as at 31.12.2024
... B71: APPENDIX 54 | C71: APPENDIX 54 | E71: =HYPERLINK("#'" & B71 & "'!A1", C71) -> APPENDIX 54 | F71: Summary of Industry Livestock Agriculture Insurance for the Year Ended 31.12.2024

Sheet T1
C3: Table 1: Economy and Insurance Industry Trends
C6: a) Economy and Insurance Indicators
D7: Years
D8: 2013 | E8: 2014 | F8: 2015 | G8: 2016 | H8: 2017 | I8: 2018 | J8: 2019 | K8: 2020 | L8: 2021 | M8: =L8+1 -> 2022 | N8: 2023 | O8: 2024*
C9: Gross Direct Premium (KES Billion) | D9: 129.19 | E9: 155.8 | F9: 172.54012 | G9: 195.22965 | H9: 207.6 | I9: 214.9 | J9: 227.9 | K9: 233.1 | L9: 270.46828 | M9: 306.69307 | N9: 360.67855 | O9: =('APPENDIX 8'!K31+'APPENDIX 21'!Q42+'APPENDIX 46'!F10)/10^6 -> 397.06487
C10: Gross Direct Premium Growth Rate (%) | F10: 10.744623 | G10: 13.150289 | H10: =(H9/G9-1)*100 -> 6.3363086 | I10: =(I9/H9-1)*100 -> 3.5163776 | J10: =(J9/I9-1)*100 -> 6.0493253 | K10: =(K9/J9-1)*100 -> 2.2817025 | L10: 16.03101 | M10: 13.393358 | N10: 17.602447 | O10: =(O9/N9-1)*100 -> 10.088296
C11: GDP (Market Prices) KES Billion* | D11: 4745.1434 | E11: 5402.41 | F11: 6284.2 | G11: 7022.96 | H11: 8483.4 | I11: 9340.3 | J11: 10237.73 | K11: 10715.07 | L11: 12027.662 | M11: 13368.34 | N11: 15108.806 | O11: 16224.5
C12: GDP (%) growth rate (at market prices) | D12: 11.352532 | E12: 13.851354 | F12: 16.32216 | G12: 11.8 | H12: =(H11/G11-1)*100 -> 20.79522 | I12: =(I11/H11-1)*100 -> 10.100903 | J12: =(J11/I11-1)*100 -> 9.6081496 | K12: =(K11/J11-1)*100 -> 4.662557 | L12: =(L11/K11-1)*100 -> 12.249957 | M12: 11.146626 | N12: 13.019312 | O12: =(O11/N11-1)*100 -> 7.3843963
C13: Insurance Penetration ratio (%) (at current prices) | D13: 2.7225731 | E13: 2.8838981 | F13: 2.7456179 | G13: 2.78 | H13: 2.55 | I13: 2.43 | J13: 2.34 | K13: 2.1754408 | L13: 2.2487188 | M13: 2.2941747 | N13: 2.3872075 | O13: =(O9/O11)*100 -> 2.4473165
C14: Population (Million)* | D14: 41.8 | E14: 43 | F14: 44.2 | G14: 45.4 | H14: 45.3 | I14: 46.4 | J14: 47.6 | K14: 48.8 | L14: 49.7 | M14: 50.6 | N14: 51.5 | O14: 52.43
C15: Insurance Density (KES) | D15: 3090.6699 | E15: 3623.2558 | F15: 3903.6227 | G15: 4300.2125 | H15: 4455 | I15: 4525 | J15: 4788 | K15: 4776.6393 | L15: 5442.0178 | M15: 6061.1278 | N15: 7003.467 | O15: =(O9/O14)*1000 -> 7573.2381
C16: Lives Covered (Million) | D16: 2.058619 | E16: 2.470662 | F16: 4.390843 | G16: 3.82463 | H16: 4.26 | I16: 4.3 | J16: 11.65 | K16: 13.44 | L16: 13.478245 | M16: 14.22** | N16: 13.599477 | O16: ='APPENDIX 48'!G31/10^6 -> 13.530404
C17: Policies (LT,GB & Micro) (Million) | D17: 2.77243 | E17: 3.815534 | F17: 2.702272 | G17: 3.390335 | H17: 3.14 | I17: 3.43 | J17: 3.96 | L17: 4.07759 | M17: 8.713364 | N17: 12.104754 | O17: =('APPENDIX 47'!F42+'APPENDIX 48'!F31+'APPENDIX 49'!F8)/10^6 -> 14.308442
C18: Insurance cover (Lives/population) % | D18: 4.9249258 | E18: 5.7457256 | F18: 9.9340339 | G18: 8.4242952 | H18: 9.1 | I18: 9 | J18: 24.5 | K18: 27.540984 | L18: 27.119205 | M18: 28.110484 | N18: 26.406751 | O18: =(O16/O14)*100 -> 25.806608
C19: Insurance Cover (policies/population) % | D19: 6.6326077 | E19: 8.8733349 | F19: 6.1137376 | G19: 7.4676982 | H19: 6.7 | I19: 7.1 | J19: 8.3 | L19: 8.2044064 | M19: 17.220087 | N19: 23.504377 | O19: =(O17/O14)*100 -> 27.290563
C20: Rate of Inflation (%)* | D20: 5.7 | E20: 6.9 | F20: 6.6 | G20: 6.3 | H20: 8 | I20: 4.7 | J20: 5.2 | K20: 5.4 | L20: 5.62 | M20: 7.66 | N20: 7.67 | O20: 4.525
C21: Real Gross Direct Premium growth (%) | D21: 9.2156853 | E21: 12.813442 | F21: 3.8880137 | G21: 6.4442984 | H21: =(((100+H10)/(100+H20))-1)*100 -> -1.540455 | I21: =(((100+I10)/(100+I20))-1)*100 -> -1.1304894 | J21: =(((100+J10)/(100+J20))-1)*100 -> 0.80734341 | K21: =(((100+K10)/(100+K20))-1)*100 -> -2.9585365 | L21: =(((100+L10)/(100+L20))-1)*100 -> 9.857044 | M21: 5.3254299 | N21: 9.2248969 | O21: =(((100+O10)/(100+O20))-1)*100 -> 5.3224545
C22: Sources: KNBS, CBK and IRA Statistics Population in 2024 is based on 2019 projections done by KNBS *information has been updated to reflect the most updated information available **Revised
C25: b) Trend in some key insurance indicators
C26: Item | D26: Years | P26: Annual Change 2023/2024 %
D27: 2013 | E27: 2014 | F27: 2015 | G27: 2016 | H27: 2017 | I27: 2018 | J27: 2019 | K27: 2020 | L27: 2021 | M27: =L27+1 -> 2022 | N27: =M27+1 -> 2023 | O27: =O8 -> 2024*
C28: Gross Premium Income | D28: 135384923 | E28: 157732058 | F28: 174039164 | G28: 196635836 | H28: 209001296 | I28: 216261729 | J28: 229499718 | K28: 234775753 | L28: 273710831 | M28: 310273121 | N28: 3.6501795e+08 | O28: =('APPENDIX 8'!$K$31+'APPENDIX 39'!$C$42+'APPENDIX 39'!$D$42+'APPENDIX 46'!F10) -> 4.0059456e+08 | P28: =(O28-N28)/ABS(N28) *100 -> 9.7465392
C29: Net Premium Written | D29: 105013409 | E29: 126333481 | F29: 139377049 | G29: 158362431 | H29: 165852034 | I29: 172322202 | J29: 182658282 | K29: 187853004 | L29: 221133803 | M29: 249190282 | N29: 2.8749921e+08 | O29: =('APPENDIX 19'!$E$31+'APPENDIX 39'!$F$42) -> 3.2027453e+08 | P29: =(O29-N29)/ABS(N29) *100 -> 11.40014
C30: Claims Incurred (general business) | D30: 34170145 | E30: 42677696 | F30: 48811202 | G30: 54857495 | H30: 56151966 | I30: 56927996 | J30: 58961582 | K30: 58311459 | L30: 69835740 | M30: 77095546 | N30: 87688511 | O30: =SUM('APPENDIX 42'!C42:P42) -> 98762568 | P30: =(O30-N30)/ABS(N30) *100 -> 12.628857
C31: Net commissions | D31: 7204448 | E31: 14332657 | F31: 10833473 | G31: 12578735 | H31: 12495182 | I31: 11487628 | J31: 10957562 | K31: 11157093 | L31: 13521938 | M31: 15341053 | N31: 17528063 | O31: =('APPENDIX 19'!$L$31+'APPENDIX 39'!$M$42) -> 18414098 | P31: =(O31-N31)/ABS(N31) *100 -> 5.05495
C32: Expenses of Management | D32: 24808273 | E32: 49249464 | F32: 35991670 | G32: 39982771 | H32: 41197258 | I32: 44072857 | J32: 45702207 | K32: 44173611 | L32: 46513554 | M32: 50280745 | N32: 59386080 | O32: =('APPENDIX 19'!$M$31+'APPENDIX 39'!$N$42) -> 59851116 | P32: =(O32-N32)/ABS(N32) *100 -> 0.7830726
C33: Underwriting Results (general business) | D33: 3402770 | E33: 1604507 | F33: -274188 | G33: -2125731 | H33: -1027851 | I33: -2588861 | J33: -3165405 | K33: -1847726 | L33: -6333631 | M33: -3270383 | N33: -6039288.7 | O33: ='APPENDIX 39'!$O$42 -> -3678306.7 | P33: =(O33-N33)/ABS(N33) *100 -> 39.093709
C34: Investment Income(P&L) | D34: 9429214 | E34: 11095059 | F34: 6294523 | G34: 5338509 | H34: 6596592 | I34: 6967045 | J34: 9132215 | K34: 4879906 | L34: 7283075 | M34: 7041440 | N34: 72238709 | O34: ='APPENDIX 1'!$G$50+'APPENDIX 2'!$G$37 -> 1.4000145e+08 | P34: =(O34-N34)/ABS(N34) *100 -> 93.803927
C35: Operating profit/loss after taxation | D35: 20245881 | E35: 17232015 | F35: 13564434 | G35: 12835309 | H35: 13642972 | I35: 7269268 | J35: 15119928 | K35: 6388955 | L35: 8645622 | M35: 14715312 | N35: 23459372 | O35: ='APPENDIX 1'!$R$50+'APPENDIX 2'!$R$37 -> 30423137 | P35: =(O35-N35)/ABS(N35) *100 -> 29.684358
C36: Investments | D36: 296336802 | E36: 355009404 | F36: 390225346 | G36: 425304138 | H36: 483799656 | I36: 524237249 | J36: 596011648 | K36: 656460833 | L36: 733461323 | M36: 833722972 | N36: 7.1086498e+08 | O36: ='APPENDIX 5 III'!$N$46+'APPENDIX 5 III'!$O$46+'APPENDIX 6 IV'!$P$44+'APPENDIX 6 IV'!$Q$44 -> 8.6009332e+08 | P36: =(O36-N36)/ABS(N36) *100 -> 20.992501
C37: Assets | D37: 366252339 | E37: 430536097 | F37: 478752455 | G37: 528748193 | H37: 590953330 | I37: 635035110 | J37: 711247445 | K37: 765932477 | L37: 850506382 | M37: 956871079 | N37: 1.0768615e+09 | O37: ='APPENDIX 5 III'!K42+'APPENDIX 6 IV'!M40 -> 1.2520461e+09 | P37: =(O37-N37)/ABS(N37) *100 -> 16.268071
C38: Shareholder’s Funds | D38: 100958028 | E38: 114141212 | F38: 125830028 | G38: 134455222 | H38: 147255002 | I38: 149134602 | J38: 161835044 | K38: 166069303 | L38: 167914107 | M38: 184166513 | N38: 2.1043713e+08 | O38: ='APPENDIX 5 III'!$K$12+'APPENDIX 6 IV'!M11 -> 2.3206429e+08 | P38: =(O38-N38)/ABS(N38) *100 -> 10.277252
C39: Amounts in Thousands
C40: *Provisional

Sheet T2
C4: Table 2: Trends in Long-Term Insurance Business
C6: a) Summary of long term insurance business performance
C7: Indicators | D7: Years | P7: Annual Change 2023/2024 %
D8: 2013 | E8: 2014 | F8: 2015 | G8: 2016 | H8: 2017 | I8: 2018 | J8: 2019 | K8: 2020 | L8: 2021 | M8: =L8+1 -> 2022 | N8: =M8+1 -> 2023 | O8: 2024*
C9: Gross Direct Premium | D9: 44424411 | E9: 56581380 | F9: 62064805 | G9: 73519181 | H9: 82807826 | I9: 87408352 | J9: 97395510 | K9: 102078013 | L9: 123687148 | M9: 140953582 | N9: 1.7007501e+08 | O9: ='APPENDIX 19'!$D$31 -> 1.917987e+08 | P9: =(O9-N9)/ABS(N9) *100 -> 12.773001
C10: Outward Reinsurance | D10: 2731261 | E10: 3856486 | F10: 4983380 | G10: 5666993 | H10: 5860038 | I10: 7048742 | J10: 7529611 | K10: 6751093 | L10: 9081590 | M10: 12025131 | N10: 15517575 | O10: =(O9-O11) -> 14987211 | P10: =(O10-N10)/ABS(N10) *100 -> -3.4178243
C11: Net Premiums | D11: 41693150 | E11: 52718917 | F11: 57081418 | G11: 67852188 | H11: 76947788 | I11: 80359610 | J11: 89865899 | K11: 95326920 | L11: 114605558 | M11: 128928451 | N11: 1.5455744e+08 | O11: ='APPENDIX 19'!$E$31 -> 1.7681149e+08 | P11: =(O11-N11)/ABS(N11) *100 -> 14.39856
C12: Management expenses | D12: 7637766 | E12: 28460004 | F12: 11279207 | G12: 12364010 | H12: 12072033 | I12: 13928440 | J12: 15362328 | K12: 14381760 | L12: 15689550 | M12: 17456624 | N12: 20034446 | O12: ='APPENDIX 19'!$M$31 -> 22349821 | P12: =(O12-N12)/ABS(N12) *100 -> 11.556968
C13: Net Commissions | D13: 3432164 | E13: 9618165 | F13: 5152743 | G13: 5474094 | H13: 5448401 | I13: 4887507 | J13: 5277712 | K13: 5793085 | L13: 6493140 | M13: 7254217 | N13: 7727024 | O13: ='APPENDIX 19'!$L$31 -> 9157713.9 | P13: =(O13-N13)/ABS(N13) *100 -> 18.515407
C14: Life Fund C/F | D14: 137229500 | E14: 1.9329355e+08 | F14: 231885634 | G14: 255648171 | H14: 301571353 | I14: 333263364 | J14: 387780599 | K14: 426165838 | L14: 494301595 | M14: 574251284 | N14: 6.5734458e+08 | O14: ='APPENDIX 19'!$Q$31 -> 8.057781e+08 | P14: =(O14-N14)/ABS(N14) *100 -> 22.580778
C17: b) Summary of long term insurance business performance per class
C18: Indicators | E18: Years | H18: Years | P18: =P7 -> Annual Change 2023/2024 %
D19: 2013 | E19: 2014 | F19: 2015 | G19: 2016 | H19: 2017 | I19: 2018 | J19: 2019 | K19: 2020 | L19: 2021 | M19: =L19+1 -> 2022 | N19: =M19+1 -> 2023 | O19: =O8 -> 2024*
C20: Gross Direct Premium
C21: Life Assurances | D21: 13310197 | E21: 14363846 | F21: 16783137 | G21: 18880725 | H21: 21374928 | I21: 24331504 | J21: 28187025 | K21: 29549666 | L21: 34107231 | M21: 35547858 | N21: 38836382 | O21: ='APPENDIX 11'!$D$31 -> 42457066 | P21: =(O21-N21)/ABS(N21) *100 -> 9.3229177
C22: Annuities | D22: 1331213 | E22: 6358440 | F22: 4137425 | G22: 4698479 | H22: 9834902 | I22: 6880785 | J22: 7451904 | K22: 8208247 | L22: 9290658 | M22: 10036388 | N22: 12351081 | O22: ='APPENDIX 12'!$D$31 -> 12356888 | P22: =(O22-N22)/ABS(N22) *100 -> 0.047016521
C23: Personal Pensions | D23: 16089228 | E23: 14099531 | F23: 22002402 | G23: 28118598 | H23: 4497901 | I23: 4138741 | J23: 5486479 | K23: 5825247 | L23: 6804397 | M23: 8111970 | N23: 16207214 | O23: ='APPENDIX 14'!D31 -> 21729305 | P23: =(O23-N23)/ABS(N23) *100 -> 34.071809
C24: Deposit Administration | H24: 24588257 | I24: 29775545 | J24: 32237072 | K24: 34857836 | L24: 42355599 | M24: 50954518 | N24: 61704945 | O24: ='APPENDIX 15'!D31 -> 68244152 | P24: =(O24-N24)/ABS(N24) *100 -> 10.59754
C25: Group Life | D25: 3038834 | E25: 9331736 | F25: 9858591 | G25: 10600535 | H25: 12765171 | I25: 11031270 | J25: 10957689 | K25: 9665028 | L25: 14334101 | M25: 16785151 | N25: 21668737 | O25: ='APPENDIX 13'!$D$31 -> 24669467 | P25: =(O25-N25)/ABS(N25) *100 -> 13.848201
C26: Group Credit | D26: 1943 | E26: 4265352 | F26: 4816710 | G26: 6306075 | H26: 5208397 | I26: 7740166 | J26: 9516603 | K26: 10010766 | L26: 12978038 | M26: 15445861 | N26: 15748325 | O26: ='APPENDIX 16'!$D$31 -> 14560401 | P26: =IFERROR((O26-N26)/ABS(N26) *100,0) -> -7.5431748
C27: Permanent Health | D27: 6426533 | E27: 0 | F27: 0 | G27: 0 | H27: - | I27: - | J27: - | K27: - | L27: 0 | M27: 15757 | N27: 0 | O27: ='APPENDIX 17'!$D$31 -> 0 | P27: =IFERROR((O27-N27)/ABS(N27) *100,0) -> 0
C28: Investments | D28: 4226463 | E28: 8163684 | F28: 4422409 | G28: 4914770 | H28: 4538271 | I28: 3510341 | J28: 3558738 | K28: 3961223 | L28: 3817124 | M28: 4056079 | N28: 3558330.7 | O28: ='APPENDIX 18'!$D$31 -> 7781418.3 | P28: =(O28-N28)/ABS(N28) *100 -> 118.6817
C29: Total | D29: 44424411 | E29: 56582589 | F29: 62020674 | G29: 73519182 | H29: 82807826 | I29: 87408352 | J29: 97395510 | K29: 102078013 | L29: 123687148 | M29: 140953582 | N29: 1.7007501e+08 | O29: =SUM(O21:O28) -> 1.917987e+08 | P29: =(O29-N29)/ABS(N29) *100 -> 12.773001
C30: Net Premiums
C31: Life Assurances | D31: 13114458 | E31: 14163998 | F31: 16562968 | G31: 18669399 | H31: 21122113 | I31: 24106317 | J31: 27970560 | K31: 29313231 | L31: 33862799 | M31: 35267956 | N31: 38491286 | O31: ='APPENDIX 11'!$E$31 -> 41996916 | P31: =(O31-N31)/ABS(N31) *100 -> 9.1075958
C32: Annuities | D32: 1331213 | E32: 6358440 | F32: 4137425 | G32: 4698479 | H32: 9834897 | I32: 6880785 | J32: 7451904 | K32: 8208247 | L32: 9272486 | M32: 10018249 | N32: 12332971 | O32: ='APPENDIX 12'!$E$31 -> 12338795 | P32: =(O32-N32)/ABS(N32) *100 -> 0.047221195
C33: Personal Pensions | D33: 16089228 | E33: 14099531 | F33: 22002402 | G33: 28118598 | H33: 4497901 | I33: 4138741 | J33: 5486479 | K33: 5825247 | L33: 6804397 | M33: 8111970 | N33: 16207214 | O33: ='APPENDIX 14'!E31 -> 21729305 | P33: =(O33-N33)/ABS(N33) *100 -> 34.071809
C34: Deposit Administration | H34: 24588257 | I34: 29775545 | J34: 32237072 | K34: 34857836 | L34: 42355599 | M34: 50954518 | N34: 61704945 | O34: ='APPENDIX 15'!E31 -> 68244152 | P34: =(O34-N34)/ABS(N34) *100 -> 10.59754
C35: Group Life | D35: 3020246 | E35: 6020998 | F35: 5805185 | G35: 6412173 | H35: 8666923 | I35: 5633076 | J35: 5561462 | K35: 5450274 | L35: 8154809 | M35: 9020611 | N35: 9061642.1 | O35: ='APPENDIX 13'!$E$31 -> 12198302 | P35: =IFERROR((O35-N35)/ABS(N35) *100,0) -> 34.614695
C36: Group Credit | D36: 1943 | E36: 3913711 | F36: 4106976 | G36: 5038769 | H36: 3699427 | I36: 6314805 | J36: 7599816 | K36: 7711080 | L36: 10339239 | M36: 11485915 | N36: 13201198 | O36: ='APPENDIX 16'!$E$31 -> 12522648 | P36: =IFERROR((O36-N36)/ABS(N36) *100,0) -> -5.1400607
C37: Permanent Health | D37: 4127806 | E37: 0 | F37: 0 | G37: 0 | H37: - | I37: - | J37: - | K37: - | L37: 0 | M37: 13185 | N37: 0 | O37: ='APPENDIX 17'!$E$31 -> 0 | P37: =IFERROR((O37-N37)/ABS(N37) *100,0) -> 0
C38: Investments | D38: 4008265 | E38: 8163451 | F38: 4422331 | G38: 4914770 | H38: 4538271 | I38: 3510341 | J38: 3558606 | K38: 3961005 | L38: 3816229 | M38: 4056047 | N38: 3558184.2 | O38: ='APPENDIX 18'!$E$31 -> 7781368.2 | P38: =(O38-N38)/ABS(N38) *100 -> 118.6893
C39: Total | D39: 41693149 | E39: 52720129 | F39: 57037287 | G39: 67852188 | H39: 76947788 | I39: 80359610 | J39: 89865899 | K39: 95326920 | L39: 114605558 | M39: 128928451 | N39: 1.5455744e+08 | O39: =SUM(O31:O38) -> 1.7681149e+08 | P39: =(O39-N39)/ABS(N39) *100 -> 14.39856
C40: Net Commissions
C41: Life Assurances | D41: 2930874 | E41: 3184836 | F41: 3760565 | G41: 4314129 | H41: 4089626 | I41: 3841617 | J41: 4178191 | K41: 4406912 | L41: 4344451 | M41: 4709382 | N41: 5554528.5 | O41: ='APPENDIX 11'!$L$31 -> 5927242.1 | P41: =IFERROR((O41-N41)/ABS(N41) *100,0) -> 6.7100854
C42: Annuities | D42: 18430 | E42: 137180 | F42: 103094 | G42: 71677 | H42: 174395 | I42: 111012 | J42: 156043 | K42: 164128 | L42: 174330 | M42: 194641 | N42: 215563.3 | O42: ='APPENDIX 12'!$L$31 -> 250142.9 | P42: =IFERROR((O42-N42)/ABS(N42) *100,0) -> 16.041504
C43: Personal Pensions | D43: 134547 | E43: 161911 | F43: 191723 | G43: 350075 | H43: 55033 | I43: 39355 | J43: 61199 | K43: 68987 | L43: 86775 | M43: 97312 | N43: 130552.5 | O43: ='APPENDIX 14'!L31 -> 198223.95 | P43: =IFERROR((O43-N43)/ABS(N43) *100,0) -> 51.834656
C44: Deposit Administration | H44: 265098 | I44: 283451 | J44: 332644 | K44: 333964 | L44: 445466 | M44: 628537 | N44: 709036.13 | O44: ='APPENDIX 15'!L31 -> 953381.9 | P44: =IFERROR((O44-N44)/ABS(N44) *100,0) -> 34.461682
C45: Group Life | D45: 128988 | E45: 92494 | F45: 222082 | G45: 89220 | H45: 351110 | I45: -56828 | J45: -338650 | K45: -64499 | L45: 598376 | M45: 308784 | N45: 326283.4 | O45: ='APPENDIX 13'!$L$31 -> 120575.49 | P45: =IFERROR((O45-N45)/ABS(N45) *100,0) -> -63.04578
C46: Group Credit | D46: 13 | E46: 189041 | F46: 441028 | G46: 427617 | H46: 319000 | I46: 479268 | J46: 511910 | K46: 757675 | L46: 735799 | M46: 1246815 | N46: 711495.43 | O46: ='APPENDIX 16'!$L$31 -> 1601621.5 | P46: =IFERROR((O46-N46)/ABS(N46) *100,0) -> 125.10637
...

Sheet T3
C4: Table 3: Trends in General Insurance Business
C7: a) Classwise GDP under general insurance business
C8: Class of business | D8: Years | P8: Annual Change 2023/2024 %
D9: 2013 | E9: 2014 | F9: 2015 | G9: 2016 | H9: 2017 | I9: 2018 | J9: 2019 | K9: 2020 | L9: 2021 | M9: =L9+1 -> 2022 | N9: =M9+1 -> 2023 | O9: 2024*
C10: Aviation | D10: 1127429 | E10: 1200632 | F10: 1484892 | G10: 1476801 | H10: 1726496 | I10: 2134254 | J10: 2109320 | K10: 2963413 | L10: 3094410 | M10: 3564550 | N10: 4558254.5 | O10: ='[1]APPENDIX 21'!C$42 -> 4879911.3 | P10: =(O10-N10)/ABS(N10) *100 -> 7.0565769
C11: Engineering | D11: 2776577 | E11: 3547973 | F11: 3794202 | G11: 3473125 | H11: 4190323 | I11: 3691508 | J11: 3502268 | K11: 3249381 | L11: 4283167 | M11: 5064942 | N11: 4418421.4 | O11: ='[1]APPENDIX 21'!D$42 -> 4992920.1 | P11: =(O11-N11)/ABS(N11) *100 -> 13.002351
C12: Fire Domestic | D12: 1272835 | E12: 1347967 | F12: 1388204 | G12: 1482865 | H12: 1570425 | I12: 1595804 | J12: 1672639 | K12: 1795320 | L12: 1770893 | M12: 1815381 | N12: 2033724.9 | O12: ='[1]APPENDIX 21'!E$42 -> 2081468.1 | P12: =(O12-N12)/ABS(N12) *100 -> 2.3475777
C13: Fire industrial | D13: 7637802 | E13: 8757929 | F13: 9547284 | G13: 10062935 | H13: 11130626 | I13: 10824386 | J13: 10870577 | K13: 10776438 | L13: 12949770 | M13: 16828541 | N13: 19599395 | O13: ='[1]APPENDIX 21'!F$42 -> 21870299 | P13: =(O13-N13)/ABS(N13) *100 -> 11.586599
C14: Liability | D14: 1560128 | E14: 1891331 | F14: 2191880 | G14: 2520106 | H14: 2817584 | I14: 2728902 | J14: 3124267 | K14: 3124468 | L14: 3358022 | M14: 3723336 | N14: 4657601.9 | O14: ='[1]APPENDIX 21'!G$42 -> 5224758.4 | P14: =(O14-N14)/ABS(N14) *100 -> 12.177008
C15: Marine | D15: 2775148 | E15: 2726463 | F15: 2852402 | G15: 2604270 | H15: 3555639 | I15: 3370608 | J15: 3188714 | K15: 3063641 | L15: 3637910 | M15: 4054753 | N15: 4350308.1 | O15: ='[1]APPENDIX 21'!H$42 -> 4739988.1 | P15: =(O15-N15)/ABS(N15) *100 -> 8.9575253
C16: Motor Private | D16: 13909445 | E16: 16382944 | F16: 18430997 | G16: 20460256 | H16: 21484964 | I16: 22495605 | J16: 23431002 | K16: 23449022 | L16: 24626670 | M16: 27855160 | N16: 30182712 | O16: ='[1]APPENDIX 21'!I$42 -> 30668659 | P16: =(O16-N16)/ABS(N16) *100 -> 1.6100179
C17: Motor Commercial | D17: 19536285 | E17: 22553021 | F17: 24091465 | G17: 24025770 | H17: 23226291 | I17: 23593081 | J17: 23049684 | K17: 21279353 | L17: 24279823 | M17: 26132363 | N17: 26508100 | O17: =('[1]APPENDIX 21'!J$42+'[1]APPENDIX 21'!K$42) -> 27120958 | P17: =(O17-N17)/ABS(N17) *100 -> 2.3119667
C18: Personal Accident | D18: 3250304 | E18: 3604559 | F18: 3882018 | G18: 3997282 | H18: 3516204 | I18: 3157233 | J18: 3283857 | K18: 2362292 | L18: 2400674 | M18: 2331266 | N18: 2911861.4 | O18: ='[1]APPENDIX 21'!L$42 -> 2995600.5 | P18: =(O18-N18)/ABS(N18) *100 -> 2.8757937
C19: Theft | D19: 3289650 | E19: 3553715 | F19: 3786845 | G19: 3774820 | H19: 3784701 | I19: 3863654 | J19: 3835945 | K19: 3851366 | L19: 3992205 | M19: 4119725 | N19: 4804844.9 | O19: ='[1]APPENDIX 21'!M$42 -> 5479902.4 | P19: =(O19-N19)/ABS(N19) *100 -> 14.049517
C20: Workmen's Compensation | D20: 4666576 | E20: 5174648 | F20: 5346077 | G20: 5601571 | H20: 5675906 | I20: 6225354 | J20: 6358473 | K20: 6233992 | L20: 10659325 | M20: 11712076 | N20: 12583481 | O20: ='[1]APPENDIX 21'!N$42 -> 12644257 | P20: =(O20-N20)/ABS(N20) *100 -> 0.48298231
C21: Medical | D21: 20507131 | E21: 25315035 | F21: 29516467 | G21: 38520439 | H21: 38337371 | I21: 40195984 | J21: 42348102 | K21: 45061539 | L21: 47586164 | M21: 54839172 | N21: 66227984 | O21: ='[1]APPENDIX 21'!O$42 -> 76203263 | P21: =(O21-N21)/ABS(N21) *100 -> 15.06203
C22: Miscellaneous | D22: 2456310 | E22: 3120075 | F22: 3487951 | G22: 3710221 | H22: 3763080 | I22: 3635343 | J22: 3741207 | K22: 3847235 | L22: 4142108 | M22: 3698214 | N22: 6865120.8 | O22: ='[1]APPENDIX 21'!P$42 -> 6129963.2 | P22: =(O22-N22)/ABS(N22) *100 -> -10.70859
C23: Total | D23: 84765620 | E23: 99176292 | F23: 109800684 | G23: 121710461 | H23: 124779610 | I23: 127511716 | J23: 130516055 | K23: 131057460 | L23: 146781141 | M23: 165739479 | N23: 1.8970181e+08 | O23: =SUM(O10:O22) -> 2.0503195e+08 | P23: =(O23-N23)/ABS(N23) *100 -> 8.0811764
C24: Amounts in '000' KES
C27: b) Incurred claims under general insurance business
C28: Class of business | D28: Years | P28: =P8 -> Annual Change 2023/2024 %
D29: 2013 | E29: 2014 | F29: 2015 | G29: 2016 | H29: 2017 | I29: 2018 | J29: 2019 | K29: 2020 | L29: 2021 | M29: =L29+1 -> 2022 | N29: =M29+1 -> 2023 | O29: =O9 -> 2024*
C30: Aviation | D30: 15144 | E30: 5915 | F30: 12888 | G30: 69815 | H30: -48571 | I30: 28336 | J30: 9285 | K30: 43775 | L30: -3515 | M30: 5880 | N30: 12740.992 | O30: ='[1]APPENDIX 42'!C$42 -> 32901.149 | P30: =(O30-N30)/ABS(N30) *100 -> 158.23067
C31: Engineering | D31: 301706 | E31: 366679 | F31: 468625 | G31: 448796 | H31: 431756 | I31: 411244 | J31: 597785 | K31: 697881 | L31: 592670 | M31: 708591 | N31: 637053.5 | O31: ='[1]APPENDIX 42'!D$42 -> 857092.66 | P31: =(O31-N31)/ABS(N31) *100 -> 34.540137
C32: Fire Domestic | D32: 337000 | E32: 289864 | F32: 483004 | G32: 523792 | H32: 309981 | I32: 477500 | J32: 414559 | K32: 394133 | L32: 421323 | M32: 205136 | N32: 378506.01 | O32: ='[1]APPENDIX 42'!E$42 -> 908594.61 | P32: =(O32-N32)/ABS(N32) *100 -> 140.04761
C33: Fire industrial | D33: 803448 | E33: 801192 | F33: 1177669 | G33: 988870 | H33: 1100373 | I33: 1141362 | J33: 825219 | K33: 1149283 | L33: 979632 | M33: 1486378 | N33: 1164292.3 | O33: ='[1]APPENDIX 42'!F$42 -> 2754740.2 | P33: =(O33-N33)/ABS(N33) *100 -> 136.60212
C34: Liability | D34: 253807 | E34: 316224 | F34: 430841 | G34: 661618 | H34: 340822 | I34: 597548 | J34: 399152 | K34: 462135 | L34: 636608 | M34: 513688 | N34: 1052329.4 | O34: ='[1]APPENDIX 42'!G$42 -> 489318.87 | P34: =(O34-N34)/ABS(N34) *100 -> -53.501358
C35: Marine | D35: 560436 | E35: 566269 | F35: 631426 | G35: 503037 | H35: 725376 | I35: 669398 | J35: 669464 | K35: 598869 | L35: 1043536 | M35: 748793 | N35: 624592.88 | O35: ='[1]APPENDIX 42'!H$42 -> 628714.52 | P35: =(O35-N35)/ABS(N35) *100 -> 0.65989199
C36: Motor Private | D36: 8784204 | E36: 10957919 | F36: 12723572 | G36: 14968463 | H36: 14181895 | I36: 14301162 | J36: 16635527 | K36: 15418425 | L36: 18015197 | M36: 19585676 | N36: 19800801 | O36: ='[1]APPENDIX 42'!I$42 -> 20554433 | P36: =(O36-N36)/ABS(N36) *100 -> 3.8060716
C37: Motor Commercial | D37: 9271908 | E37: 10746378 | F37: 12858229 | G37: 12750248 | H37: 12646816 | I37: 13618583 | J37: 15304543 | K37: 14705102 | L37: 17884591 | M37: 17686508 | N37: 19386931 | O37: =('[1]APPENDIX 42'!J$42+'[1]APPENDIX 42'!K$42) -> 20440523 | P37: =(O37-N37)/ABS(N37) *100 -> 5.4345455
C38: Personal Accident | D38: 884041 | E38: 1296968 | F38: 672415 | G38: 1237073 | H38: 1081310 | I38: 747352 | J38: 464566 | K38: 481601 | L38: 1063712 | M38: -294008 | N38: 266099.71 | O38: ='[1]APPENDIX 42'!L$42 -> 255250.56 | P38: =(O38-N38)/ABS(N38) *100 -> -4.0770961
C39: Theft | D39: 1143607 | E39: 1238056 | F39: 770640 | G39: 1192206 | H39: 969900 | I39: 1304641 | J39: 887812 | K39: 722603 | L39: 860395 | M39: 694374 | N39: 979561.85 | O39: ='[1]APPENDIX 42'!M$42 -> 1352820.5 | P39: =(O39-N39)/ABS(N39) *100 -> 38.10465
C40: Workmen's Compensation | D40: 2024589 | E40: 2649305 | F40: 2666925 | G40: 2987368 | H40: 3126587 | I40: 2374487 | J40: 1548271 | K40: 1910300 | L40: 1752873 | M40: 2291780 | N40: 2846599.2 | O40: ='[1]APPENDIX 42'!N$42 -> 3056513.2 | P40: =(O40-N40)/ABS(N40) *100 -> 7.3742048
C41: Medical | D41: 9260252 | E41: 12774064 | F41: 15063107 | G41: 18095577 | H41: 20632162 | I41: 20515402 | J41: 20424313 | K41: 20975226 | L41: 25941119 | M41: 32583822 | N41: 39104741 | O41: ='[1]APPENDIX 42'!O$42 -> 46113366 | P41: =(O41-N41)/ABS(N41) *100 -> 17.922696
C42: Miscellaneous | D42: 529996 | E42: 668871 | F42: 851856 | G42: 430629 | H42: 653554 | I42: 740981 | J42: 781086 | K42: 752126 | L42: 647599 | M42: 878928 | N42: 1434261.9 | O42: ='[1]APPENDIX 42'!P$42 -> 1318299.7 | P42: =(O42-N42)/ABS(N42) *100 -> -8.085146
C43: Total | D43: 34170138 | E43: 42677704 | F43: 48811197 | G43: 54857492 | H43: 56151961 | I43: 56927996 | J43: 58961582 | K43: 58311459 | L43: 69835740 | M43: 77095546 | N43: 87688511 | O43: =SUM(O30:O42) -> 98762568 | P43: =(O43-N43)/ABS(N43) *100 -> 12.628857
C44: Amounts in '000' KES
C47: c) Classwise underwriting results- General
C48: Class of business | D48: Years | P48: =P8 -> Annual Change 2023/2024 %
D49: 2013 | E49: 2014 | F49: 2015 | G49: 2016 | H49: 2017 | I49: 2018 | J49: 2019 | K49: 2020 | L49: 2021 | M49: =L49+1 -> 2022 | N49: =M49+1 -> 2023 | O49: =O9 -> 2024*
...

Sheet T4
C4: Table 3: Trends in Microinsurance Business
C7: a) Classwise GDP under microinsurance business
C8: Class of business | E8: Distribution 2024 %
D9: 2024*
C10: Life | D10: {=TRANSPOSE('[1]APPENDIX 46'!C10:E10)} -> 2573.596 | E10: =($D10/$D$13)*100 -> 1.0987666
C11: General | D11: 224030.32 | E11: =($D11/$D$13)*100 -> 95.64711
C12: Bundled | D12: 7622 | E12: =($D12/$D$13)*100 -> 3.2541233
C13: Total | D13: =SUM(D10:D12) -> 234225.91 | E13: =($D13/$D$13)*100 -> 100
C14: Amounts in '000' KES
C17: b) Incurred claims under microinsurance business
C18: Class of business | E18: =E8 -> Distribution 2024 %
D19: =D9 -> 2024*
C20: Life | D20: {=TRANSPOSE('[1]APPENDIX 46'!I17:K17)} -> 470.147 | E20: =($D20/$D$23)*100 -> 1.5829063
C21: General | D21: 27954.209 | E21: =($D21/$D$23)*100 -> 94.117147
C22: Bundled | D22: 1277.149 | E22: =($D22/$D$23)*100 -> 4.2999471
C23: Total | D23: =SUM(D20:D22) -> 29701.505 | E23: =($D23/$D$23)*100 -> 100
C24: Amounts in '000' KES
C27: c) Classwise claims paid under Microinsurance business
C28: Class of business | E28: =E8 -> Distribution 2024 %
D29: =D9 -> 2024*
C30: Life | D30: {=TRANSPOSE('[1]APPENDIX 46'!I10:K10)} -> 247.396 | E30: =($D30/$D$33) *100 -> 0.72990965
C31: General | D31: 32741.462 | E31: =($D31/$D$33) *100 -> 96.599416
C32: Bundled | D32: 905.2 | E32: =($D32/$D$33) *100 -> 2.6706746
C33: Total | D33: =SUM(D30:D32) -> 33894.058 | E33: =($D33/$D$33) *100 -> 100
C34: Amounts in '000' KES
C35: *Provisional

Sheet T5
C5: Table 4: Trends in Re-Insurance Business
C7: a) Performance for long term reinsurers
C8: Item | D8: Years | P8: Annual Change 2023/2024 %
D9: 2013 | E9: 2014 | F9: 2015 | G9: 2016 | H9: 2017 | I9: 2018 | J9: 2019 | K9: 2020 | L9: 2021 | M9: =L9+1 -> 2022 | N9: =M9+1 -> 2023 | O9: 2024*
C10: Life Assurances
C11: Inward reinsurance premium | D11: 174580 | E11: 134022 | F11: 114245 | G11: 152658 | H11: 179830 | I11: 239839 | J11: 246317 | K11: 239008 | L11: 96544 | M11: 294833 | N11: 163636.36 | O11: ='[1]APPENDIX 11'!D36 -> 216341.66 | P11: =(O11-N11)/ABS(N11) *100 -> 32.208793
C12: Outward reinsurance premium | D12: 18743 | E12: 1971 | F12: 4689 | G12: 17602 | H12: 22747 | I12: 10701 | J12: 10826 | K12: 60950 | L12: 12676 | M12: 9734 | N12: -8370.834 | O12: =O11-O13 -> 27316.379 | P12: =(O12-N12)/ABS(N12) *100 -> 426.32804
C13: Net premium income | D13: 155837 | E13: 119828 | F13: 119828 | G13: 135056 | H13: 157083 | I13: 229138 | J13: 235491 | K13: 178058 | L13: 83868 | M13: 285099 | N13: 172007.2 | O13: ='[1]APPENDIX 11'!$E$36 -> 189025.28 | P13: =(O13-N13)/ABS(N13) *100 -> 9.8938213
C14: Management expenses | D14: 29506 | E14: 71834 | F14: 54739 | G14: 18330 | H14: 26601 | I14: 25995 | J14: 27293 | K14: 38231 | L14: 42152 | M14: 19968 | N14: 7237.4876 | O14: ='[1]APPENDIX 11'!$M$36 -> 20872.755 | P14: =(O14-N14)/ABS(N14) *100 -> 188.3978
C15: Net commissions | D15: 50521 | E15: 21550 | F15: 21550 | G15: 59375 | H15: 47993 | I15: 29873 | J15: 62932 | K15: 57205 | L15: 18673 | M15: 69592 | N15: 45172.838 | O15: ='[1]APPENDIX 11'!$L$36 -> 60180.861 | P15: =(O15-N15)/ABS(N15) *100 -> 33.223556
C16: Life fund c/f | D16: 1033636 | E16: 1171464 | F16: 1177990 | G16: 1203305 | H16: 1241040 | I16: 1386391 | J16: 1496517 | K16: 1534174 | L16: 1617766 | M16: 1773012 | N16: 514261.87 | O16: ='[1]APPENDIX 11'!Q36 -> 570243.66 | P16: =(O16-N16)/ABS(N16) *100 -> 10.885854
C17: Group Life
C18: Inward reinsurance premium | D18: 1318142 | E18: 1485325 | F18: 1971822 | G18: 2247254 | H18: 2591325 | I18: 3014166 | J18: 3545208 | K18: 2906584 | L18: 3033758 | M18: 2783551 | N18: 3545454.1 | O18: ='[1]APPENDIX 13'!$D$36 -> 4024420 | P18: =(O18-N18)/ABS(N18) *100 -> 13.509295
C19: outward reinsurance premium | D19: 146482 | E19: 32671 | F19: 48362 | G19: 305800 | H19: 303096 | I19: 324320 | J19: 387934 | K19: 267328 | L19: 334085 | M19: 313071 | N19: 2953229.3 | O19: =O18-O20 -> 409398.08 | P19: =(O19-N19)/ABS(N19) *100 -> -86.137274
C20: Net premium income | D20: 1171660 | E20: 1301827 | F20: 1718421 | G20: 1941454 | H20: 2288229 | I20: 2689846 | J20: 3157274 | K20: 2639256 | L20: 2699673 | M20: 2470480 | N20: 592224.78 | O20: ='[1]APPENDIX 13'!$E$36 -> 3615021.9 | P20: =(O20-N20)/ABS(N20) *100 -> 510.41382
C21: Management expenses | D21: 218806 | E21: 558274 | F21: 699719 | G21: 249450 | H21: 325124 | I21: 302888 | J21: 353897 | K21: 220382 | L21: 372816 | M21: 190833 | N21: -8482.7292 | O21: ='[1]APPENDIX 13'!$M$36 -> 253100.04 | P21: =(O21-N21)/ABS(N21) *100 -> 3083.71
C22: Net commissions | D22: 283922 | E22: 224720 | F22: 287252 | G22: 546986 | H22: 624144 | I22: 751119 | J22: 896634 | K22: 766785 | L22: 680777 | M22: 661340 | N22: 704866.39 | O22: ='[1]APPENDIX 13'!$L$36 -> 1090700.3 | P22: =(O22-N22)/ABS(N22) *100 -> 54.738583
C23: Life fund | D23: 4491195 | E23: 5121829 | F23: 5748174 | G23: 5445849 | H23: 5975024 | I23: 6315119 | J23: 7372750 | K23: 8132130 | L23: 8872267 | M23: 10979707 | N23: 7353568.3 | O23: ='[1]APPENDIX 13'!Q36 -> 9023495.5 | P23: =(O23-N23)/ABS(N23) *100 -> 22.709072
C24: Amounts in '000' KES
C27: b) Underwriting results under general reinsurance business
C28: Class of business | D28: Years | P28: =P8 -> Annual Change 2023/2024 %
D29: 2013 | E29: 2014 | F29: 2015 | G29: 2016 | H29: 2017 | I29: 2018 | J29: 2019 | K29: 2020 | L29: 2021 | M29: =L29+1 -> 2022 | N29: =M29+1 -> 2023 | O29: =O9 -> 2024*
C30: Aviation | D30: 3331 | E30: -22366 | F30: 74718 | G30: -19756 | H30: -12834 | I30: 4542 | J30: -18729 | K30: -1077 | L30: 12288 | M30: -7566 | N30: 86421.122 | O30: ='[1]APPENDIX 44'!C$49 -> 7991.4753 | P30: =(O30-N30)/ABS(N30) *100 -> -90.752868
C31: Engineering | D31: 280151 | E31: 110074 | F31: 228806 | G31: 205944 | H31: 172210 | I31: 223258 | J31: 275016 | K31: -480240 | L31: -228919 | M31: 242981 | N31: 634761.44 | O31: ='[1]APPENDIX 44'!D$49 -> 718617.22 | P31: =(O31-N31)/ABS(N31) *100 -> 13.210598
C32: Fire Domestic | D32: -9183 | E32: 1862 | F32: 329788 | G32: -19084 | H32: 8328 | I32: 6529 | J32: 528720 | K32: 688589 | L32: 7543 | M32: 77166 | N32: -258786.17 | O32: ='[1]APPENDIX 44'!E$49 -> -410525.79 | P32: =(O32-N32)/ABS(N32) *100 -> -58.635132
C33: Fire industrial | D33: 560765 | E33: 629912 | F33: -691401 | G33: -671791 | H33: -612432 | I33: -38213 | J33: -245061 | K33: -358002 | L33: 737729 | M33: 1043748 | N33: -635116.85 | O33: ='[1]APPENDIX 44'!F$49 -> 670535 | P33: =(O33-N33)/ABS(N33) *100 -> 205.57664
C34: Liability | D34: 39519 | E34: 85149 | F34: 46463 | G34: 63275 | H34: 51506 | I34: 109221 | J34: 82632 | K34: 86751 | L34: 128529 | M34: 63606 | N34: 164119.31 | O34: ='[1]APPENDIX 44'!G$49 -> -1046906 | P34: =(O34-N34)/ABS(N34) *100 -> -737.89327
C35: Marine | D35: 140630 | E35: 286894 | F35: 80212 | G35: 47746 | H35: 152505 | I35: -88587 | J35: -2835 | K35: 272698 | L35: 37675 | M35: -161572 | N35: 104092.73 | O35: ='[1]APPENDIX 44'!H$49 -> 333210.11 | P35: =(O35-N35)/ABS(N35) *100 -> 220.10893
C36: Motor Private | D36: 3145 | E36: 8360 | F36: 7999 | G36: 18107 | H36: 48544 | I36: 27724 | J36: 29459 | K36: -581735 | L36: 72407 | M36: 321433 | N36: 52289.865 | O36: ='[1]APPENDIX 44'!I$49 -> -62706.766 | P36: =(O36-N36)/ABS(N36) *100 -> -219.92145
C37: Motor Commercial | D37: 91193 | E37: 102325 | F37: 644 | G37: 120356 | H37: 269786 | I37: -122896 | J37: -828633 | K37: -1043466 | L37: -31434 | M37: 8677 | N37: -80579.038 | O37: =('[1]APPENDIX 44'!J$49+'[1]APPENDIX 44'!K49) -> 295163.42 | P37: =(O37-N37)/ABS(N37) *100 -> 466.30299
C38: Personal Accident | D38: -109200 | E38: -379110 | F38: -93734 | G38: 583453 | H38: 38268 | I38: -189387 | J38: -2583962 | K38: 2132340 | L38: 68492 | M38: 295464 | N38: 751834.8 | O38: ='[1]APPENDIX 44'!L$49 -> 1393776.3 | P38: =(O38-N38)/ABS(N38) *100 -> 85.383319
C39: Theft | D39: -205259 | E39: -150893 | F39: 106261 | G39: 142121 | H39: 264811 | I39: 101026 | J39: 255472 | K39: 8109 | L39: 108588 | M39: 24356 | N39: -154875.58 | O39: ='[1]APPENDIX 44'!M$49 -> 117080.71 | P39: =(O39-N39)/ABS(N39) *100 -> 175.59663
C40: Workmen's Compensation | D40: -4749 | E40: 9437 | F40: 234983 | G40: 3264 | H40: 9140 | I40: 3768 | J40: -7463 | K40: -18506 | L40: 169666 | M40: 140034 | N40: 642024.69 | O40: ='[1]APPENDIX 44'!N$49 -> 28493.74 | P40: =(O40-N40)/ABS(N40) *100 -> -95.561893
C41: Medical | D41: -672213 | E41: -369149 | F41: -525036 | G41: -650108 | H41: -236752 | I41: -1191497 | J41: 1144582 | K41: -1388992 | L41: -897875 | M41: -708115 | N41: 813644.99 | O41: ='[1]APPENDIX 44'!O$49 -> -63595.435 | P41: =(O41-N41)/ABS(N41) *100 -> -107.81612
C42: Miscellaneous | D42: 115441 | E42: 96243 | F42: 373455 | G42: 464570 | H42: 230594 | I42: 658724 | J42: -1090774 | K42: 959588 | L42: 254690 | M42: -143925 | N42: -247198.5 | O42: ='[1]APPENDIX 44'!P$49 -> 353698.27 | P42: =(O42-N42)/ABS(N42) *100 -> 243.08269
C43: Total | D43: 233571 | E43: 408738 | F43: 173158 | G43: 288097 | H43: 383674 | I43: -495788 | J43: -2461576 | K43: 276057 | L43: 439379 | M43: 1196287 | N43: =SUM(N30:N42) -> 1872632.8 | O43: =SUM(O30:O42) -> 2334832.2 | P43: =(O43-N43)/ABS(N43) *100 -> 24.681797
C44: Amounts in '000' KES
C45: *Provisional
C46: a) Performance for general reinsurers
C47: Item | D47: Years | P47: Annual Change 2023/2024 %
...

Sheet APPENDIX 1
B3: =_xlfn.CONCAT(Contents!E13,": ", UPPER(Contents!F13)) -> APPENDIX 1: SUMMARY OF PROFIT & LOSS ACCOUNTS UNDER GENERAL INSURANCE BUSINESS FOR THE YEAR ENDED 31.12.2024
B4: Company | C4: Insurance Revenue | D4: Insurance Service Expense | E4: Net expenses from reinsurance contracts held | F4: Insurance Service Result | G4: Net Investment Income | H4: Finance expenses from insurance contracts | I4: Finance income from reinsurance contracts | J4: Net Financial Result | K4: Asset management services revenue | L4: Other Income | M4: Other finance costs | N4: Other operating expenses | O4: Share of profit of associates and joint ventures accounted for using the equity method | P4: Profit before income tax | Q4: Income tax expense | R4: Profit for the year
B5: INSURERS
B6: AAR INSURANCE KENYA | C6: {='[1]APPENDIX 1'!$C6:$R6} -> 10696270 | D6: 9983608 | E6: 125557.97 | F6: 587104.41 | G6: 647371.18 | H6: 0 | I6: 0 | J6: 647371.18 | K6: 0 | L6: 5413.7566 | M6: 14759.758 | N6: 689274.94 | O6: 0 | P6: 535854.64 | Q6: 152386.02 | R6: 383468.63
B7: AFRICA MERCHANT ASSURANCE | C7: {='[1]APPENDIX 1'!$C7:$R7} -> 3226047.5 | D7: 2060274.8 | E7: 313195.52 | F7: 852577.18 | G7: 128612.09 | H7: 461615.43 | I7: 77095.661 | J7: -255907.68 | K7: 0 | L7: 0 | M7: 0 | N7: 456086.41 | O7: 0 | P7: 140583.09 | Q7: 38611.511 | R7: 101971.57
B8: APA INSURANCE LIMITED | C8: {='[1]APPENDIX 1'!$C8:$R8} -> 17460597 | D8: 14418179 | E8: 2360727.3 | F8: 681690.01 | G8: 1546494 | H8: 1493994.3 | I8: 582463.29 | J8: 634963.01 | K8: 0 | L8: 0 | M8: 28516.615 | N8: 394977.1 | O8: 39425.079 | P8: 932584.38 | Q8: -116196.02 | R8: 1048780.4
B9: BRITAM GENERAL INSURANCE | C9: {='[1]APPENDIX 1'!$C9:$R9} -> 16975459 | D9: 12306514 | E9: 3527521.7 | F9: 1141423.3 | G9: 1835535.8 | H9: 1436494.4 | I9: 634898.77 | J9: 1033940.2 | K9: 0 | L9: 58068.088 | M9: 40850.592 | N9: 564376 | O9: 0 | P9: 1628205 | Q9: 376427.17 | R9: 1251777.8
B10: CANNON GENERAL INSURANCE (K) LIMITED | C10: {='[1]APPENDIX 1'!$C10:$R10} -> 1807225.3 | D10: 2344306.5 | E10: -27028.26 | F10: -510052.93 | G10: 722005.51 | H10: 84537.928 | I10: 66941.464 | J10: 704409.04 | K10: 0 | L10: 0 | M10: 0 | N10: 226084.85 | O10: 0 | P10: -31728.742 | Q10: 90445.995 | R10: -122174.74
B11: CIC GENERAL INSURANCE COMPANY | C11: {='[1]APPENDIX 1'!$C11:$R11} -> 15967867 | D11: 15151627 | E11: 483965.2 | F11: 332275.47 | G11: 1323008 | H11: 615744.7 | I11: 183574.69 | J11: 890838 | K11: 0 | L11: 350844.45 | M11: 0 | N11: 355159.82 | O11: 0 | P11: 1218798.1 | Q11: 363651.69 | R11: 855146.41
B12: CORPORATE INSURANCE COMPANY | C12: {='[1]APPENDIX 1'!$C12:$R12} -> 218819.36 | D12: 134569.95 | E12: 5376.985 | F12: 78872.428 | G12: 2059.9852 | H12: 115165.35 | I12: 39392.553 | J12: -73712.807 | K12: 0 | L12: 0 | M12: 0 | N12: 113725.59 | O12: 0 | P12: -108565.97 | Q12: 0 | R12: -108565.97
B13: DIRECTLINE ASSURANCE COMPANY | C13: {='[1]APPENDIX 1'!$C13:$R13} -> 4250992.4 | D13: 5127752.7 | E13: 64869.75 | F13: -941630.07 | G13: 270924.45 | H13: 928143.89 | I13: 0 | J13: -657219.44 | K13: 0 | L13: 0 | M13: 0 | N13: 88323.379 | O13: 0 | P13: -1687172.9 | Q13: -488004.96 | R13: -1199167.9
B14: EQUITY GENERAL INSURANCE | C14: {='[1]APPENDIX 1'!$C14:$R14} -> 0 | D14: 0 | E14: 0 | F14: 0 | G14: 0 | H14: 0 | I14: 0 | J14: 0 | K14: 0 | L14: 0 | M14: 0 | N14: 0 | O14: 0 | P14: 0 | Q14: 0 | R14: 0
B15: FIDELITY SHIELD INSURANCE | C15: {='[1]APPENDIX 1'!$C15:$R15} -> 3771950.7 | D15: 2970623 | E15: 808337 | F15: -7009.3174 | G15: 394700.92 | H15: 171658.49 | I15: 20230.312 | J15: 243272.75 | K15: 0 | L15: 68369.225 | M15: 0 | N15: 91491.797 | O15: 0 | P15: 213140.86 | Q15: 32491.857 | R15: 180649
B16: FIRST ASSURANCE COMPANY | C16: {='[1]APPENDIX 1'!$C16:$R16} -> 5598965.4 | D16: 5294626.5 | E16: 257459.14 | F16: 46879.793 | G16: 459530 | H16: -27362.902 | I16: -46602.614 | J16: 440290.29 | K16: 0 | L16: 0 | M16: 22847 | N16: 342330.84 | O16: 0 | P16: 121992.24 | Q16: 50305 | R16: 71687.245
B17: GA INSURANCE COMPANY | C17: {='[1]APPENDIX 1'!$C17:$R17} -> 16260156 | D17: 14445384 | E17: 1301189.8 | F17: 513582.42 | G17: 1737168 | H17: 0 | I17: 0 | J17: 1737168 | K17: 0 | L17: 118866.35 | M17: 0 | N17: 116580.33 | O17: 0 | P17: 2253036.5 | Q17: 466599.02 | R17: 1786437.4
... B41: TRIDENT INSURANCE COMPANY | C41: {='[1]APPENDIX 1'!$C41:$R41} -> 0 | D41: 0 | E41: 0 | F41: 0 | G41: 0 | H41: 0 | I41: 0 | J41: 0 | K41: 0 | L41: 0 | M41: 0 | N41: 0 | O41: 0 | P41: 0 | Q41: 0 | R41: 0
B42: TOTAL | C42: =SUM(C6:C41) -> 2.0142171e+08 | D42: =SUM(D6:D41) -> 1.7207282e+08 | E42: =SUM(E6:E41) -> 21472574 | F42: =SUM(F6:F41) -> 7876317.5 | G42: =SUM(G6:G41) -> 20159476 | H42: =SUM(H6:H41) -> 9638229.6 | I42: =SUM(I6:I41) -> 3044746 | J42: =SUM(J6:J41) -> 13565993 | ... R42: =SUM(R6:R41) -> 10031308
B43: REINSURERS
B44: CONTINENTAL REINSURANCE | C44: {='[1]APPENDIX 1'!$C44:$R44} -> 6496640.2 | D44: 5666061.3 | E44: 203565 | F44: 627013.93 | G44: 298336.92 | H44: 980360.44 | I44: 345664.94 | J44: -336358.59 | K44: 0 | L44: 8063.056 | M44: 839255.76 | N44: 39711.576 | O44: 0 | P44: -580248.94 | Q44: -164703.76 | R44: -415545.18
B45: EAST AFRICA REINSURANCE | C45: {='[1]APPENDIX 1'!$C45:$R45} -> 4310410.9 | D45: 3965772.7 | E45: 173737.09 | F45: 170901.08 | G45: 757836.45 | H45: 179602.36 | I45: 30317.516 | J45: 608551.61 | K45: 0 | L45: 0 | M45: 0 | N45: 253357.52 | O45: 0 | P45: 526095.17 | Q45: 24142.463 | R45: 501952.7
B46: GHANA REINSURANCE COMPANY | C46: {='[1]APPENDIX 1'!$C46:$R46} -> 3269656.1 | D46: 2722278.8 | E46: 55468.276 | F46: 491909.07 | G46: 267600.1 | H46: 271874.24 | I46: 60526.736 | J46: 56252.594 | K46: 0 | L46: 134.492 | M46: 238345.3 | N46: 35989.766 | O46: 0 | P46: 273961.09 | Q46: 87727.3 | R46: 186233.79
B47: KENYA REINSURANCE CORPORATION | C47: {='[1]APPENDIX 1'!$C47:$R47} -> 13125734 | D47: 9628984.6 | E47: 593204.7 | F47: 2903544.6 | G47: 4375802.1 | H47: 705255.71 | I47: -79251.863 | J47: 3591294.5 | K47: 0 | L47: 456526.95 | M47: 1947629.2 | N47: 1040377.3 | O47: 610185.62 | P47: 4573545.2 | Q47: 1823653 | R47: 2749892.2
B48: WAICA REINSURANCE KENYA LIMITED | C48: {='[1]APPENDIX 1'!$C48:$R48} -> 5514193.8 | D48: 4390883.9 | E48: -68840.898 | F48: 1192150.8 | G48: 316435.52 | H48: 354566.63 | I48: 21452.774 | J48: -16678.343 | K48: 0 | L48: 14284.854 | M48: 264167.4 | N48: 411852.48 | O48: 0 | P48: 513737.45 | Q48: 182620.51 | R48: 331116.94
B49: TOTAL | C49: =SUM(C44:C48) -> 32716635 | D49: =SUM(D44:D48) -> 26373981 | E49: =SUM(E44:E48) -> 957134.17 | F49: =SUM(F44:F48) -> 5385519.5 | G49: =SUM(G44:G48) -> 6016011.1 | H49: =SUM(H44:H48) -> 2491659.4 | I49: =SUM(I44:I48) -> 378710.1 | J49: =SUM(J44:J48) -> 3903061.8 | ... R49: =SUM(R44:R48) -> 3353650.4
B50: GRAND TOTAL | C50: =SUM(C49+C42) -> 2.3413835e+08 | D50: =SUM(D49+D42) -> 1.984468e+08 | E50: =SUM(E49+E42) -> 22429708 | F50: =SUM(F49+F42) -> 13261837 | G50: =SUM(G49+G42) -> 26175487 | H50: =SUM(H49+H42) -> 12129889 | I50: =SUM(I49+I42) -> 3423456 | J50: =SUM(J49+J42) -> 17469054 | ... R50: =SUM(R49+R42) -> 13384959
B51: Amounts in Thousand Shillings

Sheet APPENDIX 2
B3: =_xlfn.CONCAT(Contents!E14,": ",UPPER(Contents!F14)) -> APPENDIX 2: SUMMARY OF PROFIT & LOSS ACCOUNTS LONG-TERM INSURANCE BUSINESS FOR THE YEAR ENDED 31.12.2024
B4: Company | C4: Insurance Revenue | D4: Insurance Service Expense | E4: Net expenses from reinsurance contracts held | F4: Insurance Service Result | G4: Net Investment Income | H4: Finance expenses from insurance contracts | I4: Finance income from reinsurance contracts | J4: Net Financial Result | K4: Asset management services revenue | L4: Other Income | M4: Other finance costs | N4: Other operating expenses | O4: Share of profit of associates and joint ventures accounted for using the equity method | P4: Profit before income tax | Q4: Income tax expense | R4: Profit for the year
B5: INSURERS
B6: ABSA LIFE ASSURANCE | C6: {='[1]APPENDIX 2'!$C6:$R6} -> 7599467.3 | D6: 6475342.4 | E6: 317024.9 | F6: 807099.99 | G6: 1730323.1 | H6: 2237019.7 | I6: 55529.75 | J6: -451166.8 | K6: 0 | L6: 14347.04 | M6: 0 | N6: 213005.63 | O6: 0 | P6: 157274.6 | Q6: 5880.329 | R6: 151394.27
B7: APA LIFE ASSURANCE COMPANY | C7: {='[1]APPENDIX 2'!$C7:$R7} -> 2909083.8 | D7: 2439244.2 | E7: 65906.347 | F7: 403933.29 | G7: 1899444.7 | H7: 1939087.9 | I7: 13051.334 | J7: -26591.832 | K7: 0 | L7: 0 | M7: 33035.342 | N7: 84983.106 | O7: 0 | P7: 259323.01 | Q7: 58752.379 | R7: 200570.63
B8: BRITAM LIFE ASSURANCE | C8: {='[1]APPENDIX 2'!$C8:$R8} -> 13682024 | D8: 8910682.2 | E8: 1024789.7 | F8: 3746551.5 | G8: 27906944 | H8: 25312837 | I8: 149953.74 | J8: 2744060.5 | K8: 0 | L8: -26087.151 | M8: 37173.904 | N8: 1053955.9 | O8: 241950.45 | P8: 5615345.5 | Q8: 1684603.7 | R8: 3930741.9
B9: CANNON LIFE ASSURANCE (K) LIMITED | C9: {='[1]APPENDIX 2'!$C9:$R9} -> 355750.99 | D9: 476521.84 | E9: 74567.21 | F9: -195338.06 | G9: 102280.74 | H9: -44757.899 | I9: 1691.2806 | J9: 148729.92 | K9: 0 | L9: 16320 | M9: 0 | N9: 11272.251 | O9: 0 | P9: -41560.394 | Q9: 10777.369 | R9: -52337.764
B10: CAPEX LIFE ASSURANCE COMPANY | C10: {='[1]APPENDIX 2'!$C10:$R10} -> 1634045.1 | D10: 1277652 | E10: 243771.56 | F10: 112621.47 | G10: 41398.236 | H10: 17403.521 | I10: 9803.5779 | J10: 33798.293 | K10: 0 | L10: 0 | M10: 0 | N10: 20146.871 | O10: 0 | P10: 126272.89 | Q10: 0 | R10: 126272.89
B11: CIC LIFE ASSURANCE COMPANY | C11: {='[1]APPENDIX 2'!$C11:$R11} -> 6847228.7 | D11: 5140777.8 | E11: 553238.35 | F11: 1153212.5 | G11: 1978918 | H11: 4510951.3 | I11: 91380.734 | J11: -2440652.7 | K11: 0 | L11: 2650197.9 | M11: 0 | N11: 201507.98 | O11: 0 | P11: 1161249.9 | Q11: 348374.96 | R11: 812874.9
B12: CORPORATE INSURANCE COMPANY | C12: {='[1]APPENDIX 2'!$C12:$R12} -> 61268.936 | D12: 64915.463 | E12: 1091.6464 | F12: -4738.1734 | G12: 11172.979 | H12: 36967.91 | I12: 0 | J12: -25794.931 | K12: 0 | L12: 0 | M12: 0 | N12: 6254.073 | O12: 0 | P12: -36787.177 | Q12: 0 | R12: -36787.177
B13: EQUITY LIFE ASSURANCE | C13: {='[1]APPENDIX 2'!$C13:$R13} -> 1428825.5 | D13: 921101.11 | E13: 111447.7 | F13: 396276.73 | G13: 3018261.1 | H13: 1965893.5 | I13: 27880.719 | J13: 1080248.3 | K13: 0 | L13: 170193.35 | M13: 0 | N13: 254546 | O13: 0 | P13: 1392172.4 | Q13: 324581.36 | R13: 1067591
B14: GA LIFE ASSURANCE COMPANY | C14: {='[1]APPENDIX 2'!$C14:$R14} -> 95946.173 | D14: 63627.093 | E14: 29474.986 | F14: 2844.094 | G14: 5475893.4 | H14: 0 | I14: 0 | J14: 5475893.4 | K14: 0 | L14: 1091592.4 | M14: 138.053 | N14: 5109253.5 | O14: 0 | P14: 1460938.3 | Q14: 415935.89 | R14: 1045002.4
B15: GEMINIA LIFE INSURANCE COMPANY | C15: {='[1]APPENDIX 2'!$C15:$R15} -> 1096880.7 | D15: 936739.1 | E15: 45287.074 | F15: 114854.49 | G15: 277316.4 | H15: 70281.707 | I15: 0 | J15: 207034.69 | K15: 0 | L15: 0 | M15: 1427 | N15: 248994.09 | O15: 0 | P15: 71468.081 | Q15: 0 | R15: 71468.081
B16: ICEA LION LIFE ASSURANCE | C16: {='[1]APPENDIX 2'!$C16:$R16} -> 6980321.3 | D16: 4036521.2 | E16: 166682.77 | F16: 2777117.3 | G16: 26569662 | H16: 24650641 | I16: 0 | J16: 1919021 | K16: 0 | L16: 85278 | M16: 0 | N16: 953957 | O16: 0 | P16: 3827459.3 | Q16: 1001857 | R16: 2825602.3
B17: JUBILEE LIFE INSURANCE | C17: {='[1]APPENDIX 2'!$C17:$R17} -> 4833085 | D17: 4495827.5 | E17: 153272.26 | F17: 183985.2 | G17: 17069315 | H17: 13744158 | I17: 0 | J17: 3325157.1 | K17: 0 | L17: 0 | M17: 0 | N17: 680385.54 | O17: 73678 | P17: 2902434.7 | Q17: 822642.8 | R17: 2079791.9
... B30: THE MONARCH INSURANCE | C30: {='[1]APPENDIX 2'!$C30:$R30} -> 42454.027 | D30: 198249.67 | E30: -93898.978 | F30: -61896.667 | G30: 27272.32 | H30: 4584.831 | I30: 0 | J30: 22687.489 | K30: 0 | L30: 34349.652 | M30: 0 | N30: 0 | O30: 0 | P30: -4859.526 | Q30: 1658.195 | R30: -6517.721
B31: TOTAL | C31: =SUM(C6:C30) -> 70092155 | D31: =SUM(D6:D30) -> 56214894 | E31: =SUM(E6:E30) -> 3709662.9 | F31: =SUM(F6:F30) -> 10167598 | G31: =SUM(G6:G30) -> 1.1258956e+08 | H31: =SUM(H6:H30) -> 77824391 | I31: =SUM(I6:I30) -> 333038.45 | J31: =SUM(J6:J30) -> 15881465 | ... R31: =SUM(R6:R30) -> 15082705
B32: REINSURERS
B33: CONTINENTAL REINSURANCE | C33: {='[1]APPENDIX 2'!$C33:$R33} -> 17385.979 | D33: 30548.035 | E33: -2775.18 | F33: -10386.876 | G33: 51161.547 | H33: 6804.561 | I33: 60.403 | J33: 44417.389 | K33: 0 | L33: 0 | M33: 43339.828 | N33: 545.266 | O33: 0 | P33: -9854.581 | Q33: -45526.339 | R33: -55380.92
B34: EAST AFRICA REINSURANCE | C34: {='[1]APPENDIX 2'!$C34:$R34} -> 1220774.1 | D34: 985777.14 | E34: 124612.65 | F34: 110384.26 | G34: 283518.22 | H34: 26506.135 | I34: 6919.391 | J34: 263931.48 | K34: 0 | L34: 0 | M34: 0 | N34: 51111.801 | O34: 0 | P34: 323203.94 | Q34: -100303.91 | R34: 222900.03
B35: KENYA REINSURANCE CORPORATION | C35: {='[1]APPENDIX 2'!$C35:$R35} -> 2940422.8 | D35: 2575405.1 | E35: 113507.12 | F35: 251510.6 | G35: 901723.31 | H35: -82325.851 | I35: 472.115 | J35: 984521.27 | K35: 0 | L35: 0 | M35: 2.526 | N35: 66377.709 | O35: 0 | P35: 1169651.6 | Q35: 618302 | R35: 1787953.6
B36: TOTAL | C36: =SUM(C33:C35) -> 4178582.8 | D36: =SUM(D33:D35) -> 3591730.2 | E36: =SUM(E33:E35) -> 235344.59 | F36: =SUM(F33:F35) -> 351507.98 | G36: =SUM(G33:G35) -> 1236403.1 | H36: =SUM(H33:H35) -> -49015.155 | I36: =SUM(I33:I35) -> 7451.909 | J36: =SUM(J33:J35) -> 1292870.1 | ... R36: =SUM(R33:R35) -> 1955472.7
B37: GRAND TOTAL | C37: =C36+C31 -> 74270738 | D37: =D36+D31 -> 59806624 | E37: =E36+E31 -> 3945007.5 | F37: =F36+F31 -> 10519106 | G37: =G36+G31 -> 1.1382597e+08 | H37: =H36+H31 -> 77775376 | I37: =I36+I31 -> 340490.36 | J37: =J36+J31 -> 17174335 | ... R37: =R36+R31 -> 17038178
B38: Amounts in Thousand Shillings

Sheet APPENDIX 3
B3: =_xlfn.CONCAT(Contents!E15,": ",UPPER(Contents!F15)) -> APPENDIX 3: SUMMARY OF PROFIT & LOSS ACCOUNTS MICROINSURANCE BUSINESS FOR THE YEAR ENDED 31.12.2024
B4: Company | C4: Insurance Revenue | D4: Insurance Service Expense | E4: Net expenses from reinsurance contracts held | F4: Insurance Service Result | G4: Net Investment Income | H4: Finance expenses from insurance contracts | I4: Finance income from reinsurance contracts | J4: Net Financial Result | K4: Asset management services revenue | L4: Other Income | M4: Other finance costs | N4: Other operating expenses | O4: Share of profit of associates and joint ventures accounted for using the equity method | P4: Profit before income tax | Q4: Income tax expense | R4: Profit for the year
B5: INSURERS
B6: STAR DISCOVER MICRO INSURANCE | C6: {='[1]APPENDIX 3'!$C6:$R6} -> 102415.22 | D6: 80380.466 | E6: 53285.465 | F6: -31250.714 | G6: 0 | H6: 1045.1028 | I6: 895.91834 | J6: -149.18447 | K6: 0 | L6: 2423.583 | M6: 0 | N6: 252.84097 | O6: 0 | P6: -29229.157 | Q6: -8534.6161 | R6: -20694.541
B7: TURACO MICROINSURANCE | C7: {='[1]APPENDIX 3'!$C7:$R7} -> 112763.59 | D7: 94865.577 | E7: 13855.854 | F7: 4042.1546 | G7: 6535.155 | H7: 0 | I7: 0 | J7: 6535.155 | K7: 0 | L7: 0 | M7: 447.312 | N7: 5323.657 | O7: 0 | P7: 4806.3406 | Q7: 464.51431 | R7: 4341.8263
B8: TOTAL | C8: =SUM(C6:C7) -> 215178.8 | D8: =SUM(D6:D7) -> 175246.04 | E8: =SUM(E6:E7) -> 67141.319 | F8: =SUM(F6:F7) -> -27208.56 | G8: =SUM(G6:G7) -> 6535.155 | H8: =SUM(H6:H7) -> 1045.1028 | I8: =SUM(I6:I7) -> 895.91834 | J8: =SUM(J6:J7) -> 6385.9705 | ... R8: =SUM(R6:R7) -> -16352.714
B9: Amounts in Thousand Shillings

Sheet APPENDIX 4
B3: =_xlfn.CONCAT(Contents!E16,": ",UPPER(Contents!F16)) -> APPENDIX 4: SUMMARY OF NET COMMISSIONS AND MANAGEMENT EXPENSES FOR THE YEAR ENDED 31.12.2024
B5: GENERAL INSURANCE BUSINESS | F5: LONG TERM INSURANCE BUSINESS
B6: Company | C6: Commissions | D6: Management Expenses | F6: Company | G6: Commissions | H6: Management Expenses
B7: AAR INSURANCE KENYA | C7: {='[1]APPENDIX 4'!$C7:$D7} -> 661101.01 | D7: 1473817.7 | F7: ABSA LIFE ASSURANCE | G7: {='[1]APPENDIX 4'!$G7:$H7} -> 897210.76 | H7: 1039424.3
B8: AFRICA MERCHANT ASSURANCE | C8: {='[1]APPENDIX 4'!$C8:$D8} -> 320263.18 | D8: 1040963.2 | F8: APA LIFE ASSURANCE COMPANY | G8: {='[1]APPENDIX 4'!$G8:$H8} -> 541994.82 | H8: 477253.47
B9: APA INSURANCE LIMITED | C9: {='[1]APPENDIX 4'!$C9:$D9} -> 797500.83 | D9: 2492443.4 | F9: BRITAM LIFE ASSURANCE | G9: {='[1]APPENDIX 4'!$G9:$H9} -> 1536509.7 | H9: 4544020.8
B10: BRITAM GENERAL INSURANCE | C10: {='[1]APPENDIX 4'!$C10:$D10} -> 384227.53 | D10: 2795524.5 | F10: CANNON LIFE ASSURANCE (K) LIMITED | G10: {='[1]APPENDIX 4'!$G10:$H10} -> 4490.4837 | H10: 208425.3
B11: CANNON GENERAL INSURANCE (K) LIMITED | C11: {='[1]APPENDIX 4'!$C11:$D11} -> 135453.67 | D11: 567087.34 | F11: CAPEX LIFE ASSURANCE COMPANY | G11: {='[1]APPENDIX 4'!$G11:$H11} -> 100616.91 | H11: 402937.43
B12: CIC GENERAL INSURANCE COMPANY | C12: {='[1]APPENDIX 4'!$C12:$D12} -> 1307351.8 | D12: 3086692.8 | F12: CIC LIFE ASSURANCE COMPANY | G12: {='[1]APPENDIX 4'!$G12:$H12} -> 716042.15 | H12: 1872117.1
B13: CORPORATE INSURANCE COMPANY | C13: {='[1]APPENDIX 4'!$C13:$D13} -> -1326.5509 | D13: 191145.52 | F13: CORPORATE INSURANCE COMPANY | G13: {='[1]APPENDIX 4'!$G13:$H13} -> 0 | H13: 12856.517
B14: DIRECTLINE ASSURANCE COMPANY | C14: {='[1]APPENDIX 4'!$C14:$D14} -> 480946.96 | D14: 911067.82 | F14: EQUITY LIFE ASSURANCE | G14: {='[1]APPENDIX 4'!$G14:$H14} -> -11901.403 | H14: 558982.43
B15: EQUITY GENERAL INSURANCE | C15: {='[1]APPENDIX 4'!$C15:$D15} -> 0 | D15: 0 | F15: GA LIFE ASSURANCE COMPANY | G15: {='[1]APPENDIX 4'!$G15:$H15} -> 42997.084 | H15: 137387
B16: FIDELITY SHIELD INSURANCE | C16: {='[1]APPENDIX 4'!$C16:$D16} -> 212045.2 | D16: 474144.97 | F16: GEMINIA LIFE INSURANCE COMPANY | G16: {='[1]APPENDIX 4'!$G16:$H16} -> 182632.45 | H16: 138469.05
B17: FIRST ASSURANCE COMPANY | C17: {='[1]APPENDIX 4'!$C17:$D17} -> 174781.52 | D17: 1257826.5 | F17: ICEA LION LIFE ASSURANCE | G17: {='[1]APPENDIX 4'!$G17:$H17} -> 1568935.5 | H17: 2317307.4
B18: GA INSURANCE COMPANY | C18: {='[1]APPENDIX 4'!$C18:$D18} -> -170541.1 | D18: 1559423 | F18: JUBILEE LIFE INSURANCE | G18: {='[1]APPENDIX 4'!$G18:$H18} -> 1189191.6 | H18: 1469750.5
... B31: OCCIDENTAL INSURANCE COMPANY | C31: {='[1]APPENDIX 4'!$C31:$D31} -> -347214.62 | D31: 584137.62 | F31: THE MONARCH INSURANCE | G31: {='[1]APPENDIX 4'!$G31:$H31} -> -114.048 | H31: 23868.073
B32: OLD MUTUAL GENERAL INSURANCE | C32: {='[1]APPENDIX 4'!$C32:$D32} -> 1419041.7 | D32: 3261554.1 | F32: TOTAL | G32: =SUM(G7:G31) -> 9157713.9 | H32: =SUM(H7:H31) -> 22349821
B33: PACIS INSURANCE COMPANY | C33: {='[1]APPENDIX 4'!$C33:$D33} -> 252752.71 | D33: 729926.48 | F33: REINSURERS
B34: PIONEER INSURANCE COMPANY | C34: {='[1]APPENDIX 4'!$C34:$D34} -> 160751.92 | D34: 457527.06 | F34: CONTINENTAL REINSURANCE | G34: {='[1]APPENDIX 4'!$G34:$H34} -> 5479.831 | H34: 8610.053
B35: SANLAM INSURANCE COMPANY | C35: {='[1]APPENDIX 4'!$C35:$D35} -> 131623.41 | D35: 744363.01 | F35: EAST AFRICA REINSURANCE | G35: {='[1]APPENDIX 4'!$G35:$H35} -> 247715.05 | H35: 198985.03
B36: STAR DISCOVER INSURANCE | C36: {='[1]APPENDIX 4'!$C36:$D36} -> 142371.65 | D36: 284210.3 | F36: KENYA REINSURANCE CORPORATION | G36: {='[1]APPENDIX 4'!$G36:$H36} -> 897686.25 | H36: 66377.71
B37: TAKAFUL INSURANCE OF AFRICA | C37: {='[1]APPENDIX 4'!$C37:$D37} -> 73193.048 | D37: 420863.96 | F37: TOTAL | G37: =SUM(G34:G36) -> 1150881.1 | H37: =SUM(H34:H36) -> 273972.79
